<mujoco model="ur5e_1">
  <compiler angle="radian" meshdir="assets" autolimits="true"/>

  <option integrator="implicitfast"/>

  <default>
    <default class="ur5e_1">
      <material specular="0.5" shininess="0.25"/>
      <joint axis="0 1 0" range="-6.28319 6.28319" armature="0.1"/>
      <general gaintype="fixed" biastype="affine" ctrlrange="-6.2831 6.2831" gainprm="2000" biasprm="0 -2000 -400"
        forcerange="-150 150"/>
      <default class="size3_1">
        <default class="size3_limited_1">
          <joint range="-3.1415 3.1415"/>
          <general ctrlrange="-3.1415 3.1415"/>
        </default>
      </default>
      <default class="size1_1">
        <general gainprm="500" biasprm="0 -500 -100" forcerange="-28 28"/>
      </default>
      <default class="visual_1">
        <geom type="mesh" contype="0" conaffinity="0" group="2"/>
      </default>
      <default class="collision_1">
        <geom type="capsule" group="3"/>
        <default class="eef_collision_1">
          <geom type="cylinder"/>
        </default>
      </default>
      <site size="0.001" rgba="0.5 0.5 0.5 0.3" group="4"/>
    </default>
  </default>

  <asset>
    <material class="ur5e_1" name="black_1" rgba="0.033 0.033 0.033 1"/>
    <material class="ur5e_1" name="jointgray_1" rgba="0.278 0.278 0.278 1"/>
    <material class="ur5e_1" name="linkgray_1" rgba="0.82 0.82 0.82 1"/>
    <material class="ur5e_1" name="urblue_1" rgba="0.49 0.678 0.8 1"/>

    <mesh name="base_0_1" file="base_0.obj"/>
    <mesh name="base_1_1" file="base_1.obj"/>
    <mesh name="shoulder_0_1" file="shoulder_0.obj"/>
    <mesh name="shoulder_1_1" file="shoulder_1.obj"/>
    <mesh name="shoulder_2_1" file="shoulder_2.obj"/>
    <mesh name="upperarm_0_1" file="upperarm_0.obj"/>
    <mesh name="upperarm_1_1" file="upperarm_1.obj"/>
    <mesh name="upperarm_2_1" file="upperarm_2.obj"/>
    <mesh name="upperarm_3_1" file="upperarm_3.obj"/>
    <mesh name="forearm_0_1" file="forearm_0.obj"/>
    <mesh name="forearm_1_1" file="forearm_1.obj"/>
    <mesh name="forearm_2_1" file="forearm_2.obj"/>
    <mesh name="forearm_3_1" file="forearm_3.obj"/>
    <mesh name="wrist1_0_1" file="wrist1_0.obj"/>
    <mesh name="wrist1_1_1" file="wrist1_1.obj"/>
    <mesh name="wrist1_2_1" file="wrist1_2.obj"/>
    <mesh name="wrist2_0_1" file="wrist2_0.obj"/>
    <mesh name="wrist2_1_1" file="wrist2_1.obj"/>
    <mesh name="wrist2_2_1" file="wrist2_2.obj"/>
    <mesh name="wrist3_1" file="wrist3.obj"/>
  </asset>

  <worldbody>
    <light name="spotlight_1" mode="targetbodycom" target="wrist_2_link_1" pos="0 -1 2"/>
    <body name="table_1" pos="0.3 0 0.4">
      <geom name="table_geom_1" type="box" size="0.2 0.2 0.025" rgba="0.6 0.4 0.3 1"/>
      <body name="base_1" quat="1 0 0 1" childclass="ur5e_1" pos="0 0 0">
        <inertial mass="4.0" pos="0 0 0" diaginertia="0.00443333156 0.00443333156 0.0072"/>
        <geom mesh="base_0_1" material="black_1" class="visual_1"/>
        <geom mesh="base_1_1" material="jointgray_1" class="visual_1"/>
        <body name="shoulder_link_1" pos="0 0 0.163">
          <inertial mass="3.7" pos="0 0 0" diaginertia="0.0102675 0.0102675 0.00666"/>
          <joint name="shoulder_pan_joint_1" class="size3_1" axis="0 0 1"/>
          <geom mesh="shoulder_0_1" material="urblue_1" class="visual_1"/>
          <geom mesh="shoulder_1_1" material="black_1" class="visual_1"/>
          <geom mesh="shoulder_2_1" material="jointgray_1" class="visual_1"/>
          <geom class="collision_1" size="0.06 0.06" pos="0 0 -0.04"/>
          <body name="upper_arm_link_1" pos="0 0.138 0" quat="1 0 1 0">
            <inertial mass="8.393" pos="0 0 0.2125" diaginertia="0.133886 0.133886 0.0151074"/>
            <joint name="shoulder_lift_joint_1" class="size3_1"/>
            <geom mesh="upperarm_0_1" material="linkgray_1" class="visual_1"/>
            <geom mesh="upperarm_1_1" material="black_1" class="visual_1"/>
            <geom mesh="upperarm_2_1" material="jointgray_1" class="visual_1"/>
            <geom mesh="upperarm_3_1" material="urblue_1" class="visual_1"/>
            <geom class="collision_1" pos="0 -0.04 0" quat="1 1 0 0" size="0.06 0.06"/>
            <geom class="collision_1" size="0.05 0.2" pos="0 0 0.2"/>
            <body name="forearm_link_1" pos="0 -0.131 0.425">
              <inertial mass="2.275" pos="0 0 0.196" diaginertia="0.0311796 0.0311796 0.004095"/>
              <joint name="elbow_joint_1" class="size3_limited_1"/>
              <geom mesh="forearm_0_1" material="urblue_1" class="visual_1"/>
              <geom mesh="forearm_1_1" material="linkgray_1" class="visual_1"/>
              <geom mesh="forearm_2_1" material="black_1" class="visual_1"/>
              <geom mesh="forearm_3_1" material="jointgray_1" class="visual_1"/>
              <geom class="collision_1" pos="0 0.08 0" quat="1 1 0 0" size="0.055 0.06"/>
              <geom class="collision_1" size="0.038 0.19" pos="0 0 0.2"/>
              <body name="wrist_1_link_1" pos="0 0 0.392" quat="1 0 1 0">
                <inertial mass="1.219" pos="0 0.127 0" diaginertia="0.0025599 0.0025599 0.0021942"/>
                <joint name="wrist_1_joint_1" class="size1_1"/>
                <geom mesh="wrist1_0_1" material="black_1" class="visual_1"/>
                <geom mesh="wrist1_1_1" material="urblue_1" class="visual_1"/>
                <geom mesh="wrist1_2_1" material="jointgray_1" class="visual_1"/>
                <geom class="collision_1" pos="0 0.05 0" quat="1 1 0 0" size="0.04 0.07"/>
                <body name="wrist_2_link_1" pos="0 0.127 0">
                  <inertial mass="1.219" pos="0 0 0.1" diaginertia="0.0025599 0.0025599 0.0021942"/>
                  <joint name="wrist_2_joint_1" axis="0 0 1" class="size1_1"/>
                  <geom mesh="wrist2_0_1" material="black_1" class="visual_1"/>
                  <geom mesh="wrist2_1_1" material="urblue_1" class="visual_1"/>
                  <geom mesh="wrist2_2_1" material="jointgray_1" class="visual_1"/>
                  <geom class="collision_1" size="0.04 0.06" pos="0 0 0.04"/>
                  <geom class="collision_1" pos="0 0.02 0.1" quat="1 1 0 0" size="0.04 0.04"/>
                  <body name="wrist_3_link_1" pos="0 0 0.1">
                    <inertial mass="0.1889" pos="0 0.0771683 0" quat="1 0 0 1"
                      diaginertia="0.000132134 9.90863e-05 9.90863e-05"/>
                    <joint name="wrist_3_joint_1" class="size1_1"/>
                    <geom material="linkgray_1" mesh="wrist3_1" class="visual_1"/>
                    <geom class="eef_collision_1" pos="0 0.08 0" quat="1 1 0 0" size="0.04 0.02"/>
                    <site name="attachment_site_1" pos="0 0.1 0" quat="-1 1 0 0"/>
                  </body>
                </body>
              </body>
            </body>
          </body>
        </body>
      </body>
    </body>
  </worldbody>

  <actuator>
    <general class="size3_1" name="shoulder_pan_1" joint="shoulder_pan_joint_1"/>
    <general class="size3_1" name="shoulder_lift_1" joint="shoulder_lift_joint_1"/>
    <general class="size3_limited_1" name="elbow_1" joint="elbow_joint_1"/>
    <general class="size1_1" name="wrist_1_1" joint="wrist_1_joint_1"/>
    <general class="size1_1" name="wrist_2_1" joint="wrist_2_joint_1"/>
    <general class="size1_1" name="wrist_3_1" joint="wrist_3_joint_1"/>
  </actuator>

  <!-- <keyframe>
    <key name="home_1" qpos="-1.5708 -1.5708 1.5708 -1.5708 -1.5708 0" ctrl="-1.5708 -1.5708 1.5708 -1.5708 -1.5708 0"/>
    <key name="home_1" qpos="-1.5708 -1.5708 1.5708 -1.5708 -1.5708 0 -1.5708 -1.5708 1.5708 -1.5708 -1.5708 0" 
        ctrl="-1.5708 -1.5708 1.5708 -1.5708 -1.5708 0 -1.5708 -1.5708 1.5708 -1.5708 -1.5708 0"/>
  </keyframe> -->
</mujoco>
